<sdf version='1.6'>
  <model name='x1'>
  <pose frame=''>0 0 0.14236 0 -0 0</pose>
    <link name='/base_link'>
      <inertial>
        <pose frame=''>-0.00065 -0.085 0.062 0 -0 0</pose>
        <mass>46.034</mass>
        <inertia>
          <ixx>0.613201</ixx>
          <ixy>-0.0236401</ixy>
          <ixz>-0.1197</ixz>
          <iyy>1.7496</iyy>
          <iyz>-0.00154411</iyz>
          <izz>2.0406</izz>
        </inertia>
      </inertial>
      <collision name='/base_link_collision'>
        <pose frame=''>0 0 0.061875 0 -0 0</pose>
        <geometry>
          <box>
            <size>0.9874 0.5709 0.12375</size>
          </box>
        </geometry>
      </collision>
      <collision name='/base_link_collision_1'>
        <pose frame=''>0 0 0.185625 0 -0 0</pose>
        <geometry>
          <box>
            <size>0.78992 0.5709 0.12375</size>
          </box>
        </geometry>
      </collision>
      <collision name='/base_link_fixed_joint_lump__/top_plate_link_collision_2'>
        <pose frame=''>0.0812 0 0.245 0 -0 0</pose>
        <geometry>
          <mesh>
            <scale>1 1 1</scale>
            <uri>model://x1_description/meshes/top_plate.dae</uri>
          </mesh>
        </geometry>
      </collision>
      <collision name='/base_link_fixed_joint_lump__/top_plate_link_collision_3'>
        <pose frame=''>0.0812 0 0.245 0 -0 0</pose>
        <geometry>
          <box>
            <size>0.32 0.41 0.09</size>
          </box>
        </geometry>
      </collision>
      <visual name='/base_link_visual'>
        <pose frame=''>0 0 0 0 -0 -3.14159</pose>
        <geometry>
          <mesh>
            <scale>1 1 1</scale>
            <uri>model://x1_description/meshes/chassis.dae</uri>
          </mesh>
        </geometry>
      </visual>
      <visual name='/base_link_fixed_joint_lump__/center_left_headlight_link_visual_1'>
        <pose frame=''>0.485766 0.0844 0.124431 0 -0 -3.14159</pose>
        <geometry>
          <mesh>
            <scale>1 1 1</scale>
            <uri>model://x1_description/meshes/headlight.dae</uri>
          </mesh>
        </geometry>
      </visual>
      <visual name='/base_link_fixed_joint_lump__/center_right_headlight_link_visual_2'>
        <pose frame=''>0.485766 -0.0844 0.124431 0 -0 -3.14159</pose>
        <geometry>
          <mesh>
            <scale>1 1 1</scale>
            <uri>model://x1_description/meshes/headlight.dae</uri>
          </mesh>
        </geometry>
      </visual>
      <visual name='/base_link_fixed_joint_lump__/left_headlight_link_visual_3'>
        <pose frame=''>0.461459 0.216803 0.124431 0 -0 -3.14159</pose>
        <geometry>
          <mesh>
            <scale>1 1 1</scale>
            <uri>model://x1_description/meshes/headlight.dae</uri>
          </mesh>
        </geometry>
      </visual>
      <visual name='/base_link_fixed_joint_lump__marker_visual_4'>
        <pose frame=''>0.066047 0.212211 0.209188 -3.14159 1.57079 -1.60259</pose>
        <geometry>
          <mesh>
            <scale>1 1 1</scale>
            <uri>model://x1_description/meshes/led.dae</uri>
          </mesh>
        </geometry>
      </visual>
      <visual name='/base_link_fixed_joint_lump__marker_visual_5'>
        <pose frame=''>-0.066047 0.212211 0.209188 -3.14159 1.57079 -1.60259</pose>
        <geometry>
          <mesh>
            <scale>1 1 1</scale>
            <uri>model://x1_description/meshes/led.dae</uri>
          </mesh>
        </geometry>
      </visual>
      <visual name='/base_link_fixed_joint_lump__marker_visual_6'>
        <pose frame=''>-0.42493 0 0.209188 3.14159 1.57079 7e-06</pose>
        <geometry>
          <mesh>
            <scale>1 1 1</scale>
            <uri>model://x1_description/meshes/led.dae</uri>
          </mesh>
        </geometry>
      </visual>
      <visual name='/base_link_fixed_joint_lump__marker_visual_7'>
        <pose frame=''>-0.42493 0.13619 0.209188 3.14159 1.57079 7e-06</pose>
        <geometry>
          <mesh>
            <scale>1 1 1</scale>
            <uri>model://x1_description/meshes/led.dae</uri>
          </mesh>
        </geometry>
      </visual>
      <visual name='/base_link_fixed_joint_lump__marker_visual_8'>
        <pose frame=''>-0.42493 -0.13619 0.209188 3.14159 1.57079 7e-06</pose>
        <geometry>
          <mesh>
            <scale>1 1 1</scale>
            <uri>model://x1_description/meshes/led.dae</uri>
          </mesh>
        </geometry>
      </visual>
      <visual name='/base_link_fixed_joint_lump__/right_headlight_link_visual_9'>
        <pose frame=''>0.461459 -0.216803 0.124431 0 -0 -3.14159</pose>
        <geometry>
          <mesh>
            <scale>1 1 1</scale>
            <uri>model://x1_description/meshes/headlight.dae</uri>
          </mesh>
        </geometry>
      </visual>
      <visual name='/base_link_fixed_joint_lump__marker_visual_10'>
        <pose frame=''>0.066047 -0.212211 0.209188 3.14159 1.57079 1.60259</pose>
        <geometry>
          <mesh>
            <scale>1 1 1</scale>
            <uri>model://x1_description/meshes/led.dae</uri>
          </mesh>
        </geometry>
      </visual>
      <visual name='/base_link_fixed_joint_lump__marker_visual_11'>
        <pose frame=''>-0.066047 -0.212211 0.209188 3.14159 1.57079 1.60259</pose>
        <geometry>
          <mesh>
            <scale>1 1 1</scale>
            <uri>model://x1_description/meshes/led.dae</uri>
          </mesh>
        </geometry>
      </visual>
      <visual name='/base_link_fixed_joint_lump__/top_plate_link_visual_12'>
        <pose frame=''>0.0812 0 0.245 0 -0 0</pose>
        <geometry>
          <mesh>
            <scale>1 1 1</scale>
            <uri>model://x1_description/meshes/top_plate.dae</uri>
          </mesh>
        </geometry>
      </visual>
      <gravity>1</gravity>
      <velocity_decay/>
    </link>
    <link name='/front_left_wheel_link'>
      <pose frame=''>0.256 0.2854 0.03282 0 -0 0</pose>
      <inertial>
        <pose frame=''>0 0 0 0 -0 0</pose>
        <mass>2.637</mass>
        <inertia>
          <ixx>0.02467</ixx>
          <ixy>0</ixy>
          <ixz>0</ixz>
          <iyy>0.04411</iyy>
          <iyz>0</iyz>
          <izz>0.02467</izz>
        </inertia>
      </inertial>
      <collision name='/front_left_wheel_link_collision'>
        <pose frame=''>0 0 0 1.57079 -0 0</pose>
        <geometry>
          <cylinder>
            <length>0.1143</length>
            <radius>0.1651</radius>
          </cylinder>
        </geometry>
        <surface>
          <contact>
            <ode>
              <kp>1e+07</kp>
              <kd>1</kd>
            </ode>
          </contact>
          <friction>
            <ode>
              <mu>1</mu>
              <mu2>1</mu2>
              <fdir1>1 0 0</fdir1>
            </ode>
          </friction>
        </surface>
      </collision>
      <visual name='/front_left_wheel_link_visual'>
        <pose frame=''>0 0 0 0 -0 0</pose>
        <geometry>
          <mesh>
            <scale>1 1 1</scale>
            <uri>model://x1_description/meshes/wheel.dae</uri>
          </mesh>
        </geometry>
        <material>
          <script>
            <uri>__default__</uri>
            <name>__default__</name>
          </script>
        </material>
      </visual>
      <gravity>1</gravity>
      <velocity_decay/>
    </link>
    <joint name='front_left_wheel' type='revolute'>
      <child>/front_left_wheel_link</child>
      <parent>/base_link</parent>
      <axis>
        <xyz>0 1 0</xyz>
        <limit>
          <lower>-1e+16</lower>
          <upper>1e+16</upper>
        </limit>
        <dynamics>
          <spring_reference>0</spring_reference>
          <spring_stiffness>0</spring_stiffness>
        </dynamics>
        <use_parent_model_frame>1</use_parent_model_frame>
      </axis>
    </joint>
    <link name='/front_right_wheel_link'>
      <pose frame=''>0.256 -0.2854 0.03282 0 -0 0</pose>
      <inertial>
        <pose frame=''>0 0 0 0 -0 0</pose>
        <mass>2.637</mass>
        <inertia>
          <ixx>0.02467</ixx>
          <ixy>0</ixy>
          <ixz>0</ixz>
          <iyy>0.04411</iyy>
          <iyz>0</iyz>
          <izz>0.02467</izz>
        </inertia>
      </inertial>
      <collision name='/front_right_wheel_link_collision'>
        <pose frame=''>0 0 0 1.57079 -0 0</pose>
        <geometry>
          <cylinder>
            <length>0.1143</length>
            <radius>0.1651</radius>
          </cylinder>
        </geometry>
        <surface>
          <contact>
            <ode>
              <kp>1e+07</kp>
              <kd>1</kd>
            </ode>
          </contact>
          <friction>
            <ode>
              <mu>1</mu>
              <mu2>1</mu2>
              <fdir1>1 0 0</fdir1>
            </ode>
          </friction>
        </surface>
      </collision>
      <visual name='/front_right_wheel_link_visual'>
        <pose frame=''>0 0 0 0 -0 0</pose>
        <geometry>
          <mesh>
            <scale>1 1 1</scale>
            <uri>model://x1_description/meshes/wheel.dae</uri>
          </mesh>
        </geometry>
        <material>
          <script>
            <uri>__default__</uri>
            <name>__default__</name>
          </script>
        </material>
      </visual>
      <gravity>1</gravity>
      <velocity_decay/>
    </link>
    <joint name='front_right_wheel' type='revolute'>
      <child>/front_right_wheel_link</child>
      <parent>/base_link</parent>
      <axis>
        <xyz>0 1 0</xyz>
        <limit>
          <lower>-1e+16</lower>
          <upper>1e+16</upper>
        </limit>
        <dynamics>
          <spring_reference>0</spring_reference>
          <spring_stiffness>0</spring_stiffness>
        </dynamics>
        <use_parent_model_frame>1</use_parent_model_frame>
      </axis>
    </joint>
    <link name='/rear_left_wheel_link'>
      <pose frame=''>-0.256 0.2854 0.03282 0 -0 0</pose>
      <inertial>
        <pose frame=''>0 0 0 0 -0 0</pose>
        <mass>2.637</mass>
        <inertia>
          <ixx>0.02467</ixx>
          <ixy>0</ixy>
          <ixz>0</ixz>
          <iyy>0.04411</iyy>
          <iyz>0</iyz>
          <izz>0.02467</izz>
        </inertia>
      </inertial>
      <collision name='/rear_left_wheel_link_collision'>
        <pose frame=''>0 0 0 1.57079 -0 0</pose>
        <geometry>
          <cylinder>
            <length>0.1143</length>
            <radius>0.1651</radius>
          </cylinder>
        </geometry>
        <surface>
          <contact>
            <ode>
              <kp>1e+07</kp>
              <kd>1</kd>
            </ode>
          </contact>
          <friction>
            <ode>
              <mu>1</mu>
              <mu2>1</mu2>
              <fdir1>1 0 0</fdir1>
            </ode>
          </friction>
        </surface>
      </collision>
      <visual name='/rear_left_wheel_link_visual'>
        <pose frame=''>0 0 0 0 -0 0</pose>
        <geometry>
          <mesh>
            <scale>1 1 1</scale>
            <uri>model://x1_description/meshes/wheel.dae</uri>
          </mesh>
        </geometry>
        <material>
          <script>
            <uri>__default__</uri>
            <name>__default__</name>
          </script>
        </material>
      </visual>
      <gravity>1</gravity>
      <velocity_decay/>
    </link>
    <joint name='rear_left_wheel' type='revolute'>
      <child>/rear_left_wheel_link</child>
      <parent>/base_link</parent>
      <axis>
        <xyz>0 1 0</xyz>
        <limit>
          <lower>-1e+16</lower>
          <upper>1e+16</upper>
        </limit>
        <dynamics>
          <spring_reference>0</spring_reference>
          <spring_stiffness>0</spring_stiffness>
        </dynamics>
        <use_parent_model_frame>1</use_parent_model_frame>
      </axis>
    </joint>
    <link name='/rear_right_wheel_link'>
      <pose frame=''>-0.256 -0.2854 0.03282 0 -0 0</pose>
      <inertial>
        <pose frame=''>0 0 0 0 -0 0</pose>
        <mass>2.637</mass>
        <inertia>
          <ixx>0.02467</ixx>
          <ixy>0</ixy>
          <ixz>0</ixz>
          <iyy>0.04411</iyy>
          <iyz>0</iyz>
          <izz>0.02467</izz>
        </inertia>
      </inertial>
      <collision name='/rear_right_wheel_link_collision'>
        <pose frame=''>0 0 0 1.57079 -0 0</pose>
        <geometry>
          <cylinder>
            <length>0.1143</length>
            <radius>0.1651</radius>
          </cylinder>
        </geometry>
        <surface>
          <contact>
            <ode>
              <kp>1e+07</kp>
              <kd>1</kd>
            </ode>
          </contact>
          <friction>
            <ode>
              <mu>1</mu>
              <mu2>1</mu2>
              <fdir1>1 0 0</fdir1>
            </ode>
          </friction>
        </surface>
      </collision>
      <visual name='/rear_right_wheel_link_visual'>
        <pose frame=''>0 0 0 0 -0 0</pose>
        <geometry>
          <mesh>
            <scale>1 1 1</scale>
            <uri>model://x1_description/meshes/wheel.dae</uri>
          </mesh>
        </geometry>
        <material>
          <script>
            <uri>__default__</uri>
            <name>__default__</name>
          </script>
        </material>
      </visual>
      <gravity>1</gravity>
      <velocity_decay/>
    </link>
    <joint name='rear_right_wheel' type='revolute'>
      <child>/rear_right_wheel_link</child>
      <parent>/base_link</parent>
      <axis>
        <xyz>0 1 0</xyz>
        <limit>
          <lower>-1e+16</lower>
          <upper>1e+16</upper>
        </limit>
        <dynamics>
          <spring_reference>0</spring_reference>
          <spring_stiffness>0</spring_stiffness>
        </dynamics>
        <use_parent_model_frame>1</use_parent_model_frame>
      </axis>
    </joint>
    <model name='left_headlight'>
      <pose frame=''>0.461459 0.216803 0.124431 0 -0 -3.14159</pose>
      <link name='body'>
        <pose frame=''>-0.0005 0 0 0 -0 0</pose>
        <visual name='light_source'>
          <geometry>
            <mesh>
              <uri>model://x1_description/meshes/headlight_lamp.dae</uri>
            </mesh>
          </geometry>
          <transparency>1</transparency>
          <material>
            <ambient>1 1 1 1</ambient>
            <diffuse>1 1 1 1</diffuse>
            <specular>1 1 1 1</specular>
            <emissive>0 0 0 1</emissive>
          </material>
        </visual>
        <inertial>
          <mass>1e-06</mass>
          <inertia>
            <ixx>0.001</ixx>
            <ixy>0</ixy>
            <iyy>0.001</iyy>
            <ixz>0</ixz>
            <iyz>0</iyz>
            <izz>0.001</izz>
          </inertia>
        </inertial>
      </link>
    </model>
    <joint name='left_headlight' type='fixed'>
      <parent>/base_link</parent>
      <child>left_headlight::body</child>
    </joint>
    <model name='center_left_headlight'>
      <pose frame=''>0.485766 0.0844 0.124431 0 -0 -3.14159</pose>
      <link name='body'>
        <pose frame=''>-0.0005 0 0 0 -0 0</pose>
       <visual name='light_source'>
          <geometry>
            <mesh>
              <uri>model://x1_description/meshes/headlight_lamp.dae</uri>
            </mesh>
          </geometry>
          <transparency>1</transparency>
          <material>
            <ambient>1 1 1 1</ambient>
            <diffuse>1 1 1 1</diffuse>
            <specular>1 1 1 1</specular>
            <emissive>0 0 0 1</emissive>
          </material>
        </visual>
        <inertial>
          <mass>1e-06</mass>
          <inertia>
            <ixx>0.001</ixx>
            <ixy>0</ixy>
            <iyy>0.001</iyy>
            <ixz>0</ixz>
            <iyz>0</iyz>
            <izz>0.001</izz>
          </inertia>
        </inertial>
      </link>
    </model>
    <joint name='center_left_headlight' type='fixed'>
      <parent>/base_link</parent>
      <child>center_left_headlight::body</child>
    </joint>
    <model name='center_right_headlight'>
      <pose frame=''>0.485766 -0.0844 0.124431 0 -0 -3.14159</pose>
      <link name='body'>
        <pose frame=''>-0.0005 0 0 0 -0 0</pose>
        <visual name='light_source'>
          <geometry>
            <mesh>
              <uri>model://x1_description/meshes/headlight_lamp.dae</uri>
            </mesh>
          </geometry>
          <transparency>1</transparency>
          <material>
            <ambient>1 1 1 1</ambient>
            <diffuse>1 1 1 1</diffuse>
            <specular>1 1 1 1</specular>
            <emissive>0 0 0 1</emissive>
          </material>
        </visual>
        <inertial>
          <mass>1e-06</mass>
          <inertia>
            <ixx>0.001</ixx>
            <ixy>0</ixy>
            <iyy>0.001</iyy>
            <ixz>0</ixz>
            <iyz>0</iyz>
            <izz>0.001</izz>
          </inertia>
        </inertial>
      </link>
    </model>
    <joint name='center_right_headlight' type='fixed'>
      <parent>/base_link</parent>
      <child>center_right_headlight::body</child>
    </joint>
    <model name='right_headlight'>
      <pose frame=''>0.461459 -0.216803 0.124431 0 -0 -3.14159</pose>
      <link name='body'>
        <pose frame=''>-0.0005 0 0 0 -0 0</pose>
        <visual name='light_source'>
          <geometry>
            <mesh>
              <uri>model://x1_description/meshes/headlight_lamp.dae</uri>
            </mesh>
          </geometry>
          <transparency>1</transparency>
          <material>
            <ambient>1 1 1 1</ambient>
            <diffuse>1 1 1 1</diffuse>
            <specular>1 1 1 1</specular>
            <emissive>0 0 0 1</emissive>
          </material>
        </visual>
        <inertial>
          <mass>1e-06</mass>
          <inertia>
            <ixx>0.001</ixx>
            <ixy>0</ixy>
            <iyy>0.001</iyy>
            <ixz>0</ixz>
            <iyz>0</iyz>
            <izz>0.001</izz>
          </inertia>
        </inertial>
      </link>
    </model>
    <joint name='right_headlight' type='fixed'>
      <parent>/base_link</parent>
      <child>right_headlight::body</child>
    </joint>
    <model name='rear_right_led'>
      <pose frame=''>-0.42493 -0.13619 0.209188 -3.14159 1.56859 7e-06</pose>
      <link name='body'>
        <pose frame=''>0 0 0.0005 0 -0 0</pose>
        <visual name='light_source'>
          <geometry>
            <mesh>
              <uri>model://x1_description/meshes/led_lamp.dae</uri>
            </mesh>
          </geometry>
          <transparency>1</transparency>
          <material>
            <ambient>1 1 1 1</ambient>
            <diffuse>1 1 1 1</diffuse>
            <specular>1 1 1 1</specular>
            <emissive>0 0 0 1</emissive>
          </material>
        </visual>
        <inertial>
          <mass>1e-06</mass>
          <inertia>
            <ixx>0.001</ixx>
            <ixy>0</ixy>
            <iyy>0.001</iyy>
            <ixz>0</ixz>
            <iyz>0</iyz>
            <izz>0.001</izz>
          </inertia>
        </inertial>
      </link>
    </model>
    <joint name='rear_right_led' type='fixed'>
      <parent>/base_link</parent>
      <child>rear_right_led::body</child>
    </joint>
    <model name='rear_center_led'>
      <pose frame=''>-0.42493 0 0.209188 -3.14159 1.56859 7e-06</pose>
      <link name='body'>
        <pose frame=''>0 0 0.0005 0 -0 0</pose>
        <visual name='light_source'>
          <geometry>
            <mesh>
              <uri>model://x1_description/meshes/led_lamp.dae</uri>
            </mesh>
          </geometry>
          <transparency>1</transparency>
          <material>
            <ambient>1 1 1 1</ambient>
            <diffuse>1 1 1 1</diffuse>
            <specular>1 1 1 1</specular>
            <emissive>0 0 0 1</emissive>
          </material>
        </visual>
        <inertial>
          <mass>1e-06</mass>
          <inertia>
            <ixx>0.001</ixx>
            <ixy>0</ixy>
            <iyy>0.001</iyy>
            <ixz>0</ixz>
            <iyz>0</iyz>
            <izz>0.001</izz>
          </inertia>
        </inertial>
      </link>
    </model>
    <joint name='rear_center_led' type='fixed'>
      <parent>/base_link</parent>
      <child>rear_center_led::body</child>
    </joint>
    <model name='rear_left_led'>
      <pose frame=''>-0.42493 0.13619 0.209188 -3.14159 1.56859 7e-06</pose>
      <link name='body'>
        <pose frame=''>0 0 0.0005 0 -0 0</pose>
        <visual name='light_source'>
          <geometry>
            <mesh>
              <uri>model://x1_description/meshes/led_lamp.dae</uri>
            </mesh>
          </geometry>
          <transparency>1</transparency>
          <material>
            <ambient>1 1 1 1</ambient>
            <diffuse>1 1 1 1</diffuse>
            <specular>1 1 1 1</specular>
            <emissive>0 0 0 1</emissive>
          </material>
        </visual>
        <inertial>
          <mass>1e-06</mass>
          <inertia>
            <ixx>0.001</ixx>
            <ixy>0</ixy>
            <iyy>0.001</iyy>
            <ixz>0</ixz>
            <iyz>0</iyz>
            <izz>0.001</izz>
          </inertia>
        </inertial>
      </link>
    </model>
    <joint name='rear_left_led' type='fixed'>
      <parent>/base_link</parent>
      <child>rear_left_led::body</child>
    </joint>
    <model name='right_lateral_front_led'>
      <pose frame=''>0.066047 -0.212211 0.209188 3.14159 1.56859 1.60259</pose>
      <link name='body'>
        <pose frame=''>0 0 0.0005 0 -0 0</pose>
        <visual name='light_source'>
          <geometry>
            <mesh>
              <uri>model://x1_description/meshes/led_lamp.dae</uri>
            </mesh>
          </geometry>
          <transparency>1</transparency>
          <material>
            <ambient>1 1 1 1</ambient>
            <diffuse>1 1 1 1</diffuse>
            <specular>1 1 1 1</specular>
            <emissive>0 0 0 1</emissive>
          </material>
        </visual>
        <inertial>
          <mass>1e-06</mass>
          <inertia>
            <ixx>0.001</ixx>
            <ixy>0</ixy>
            <iyy>0.001</iyy>
            <ixz>0</ixz>
            <iyz>0</iyz>
            <izz>0.001</izz>
          </inertia>
        </inertial>
      </link>
    </model>
    <joint name='right_lateral_front_led' type='fixed'>
      <parent>/base_link</parent>
      <child>right_lateral_front_led::body</child>
    </joint>
    <model name='right_lateral_rear_led'>
      <pose frame=''>-0.066047 -0.212211 0.209188 3.14159 1.56859 1.60259</pose>
      <link name='body'>
        <pose frame=''>0 0 0.0005 0 -0 0</pose>
        <visual name='light_source'>
          <geometry>
            <mesh>
              <uri>model://x1_description/meshes/led_lamp.dae</uri>
            </mesh>
          </geometry>
          <transparency>1</transparency>
          <material>
            <ambient>1 1 1 1</ambient>
            <diffuse>1 1 1 1</diffuse>
            <specular>1 1 1 1</specular>
            <emissive>0 0 0 1</emissive>
          </material>
        </visual>
        <inertial>
          <mass>1e-06</mass>
          <inertia>
            <ixx>0.001</ixx>
            <ixy>0</ixy>
            <iyy>0.001</iyy>
            <ixz>0</ixz>
            <iyz>0</iyz>
            <izz>0.001</izz>
          </inertia>
        </inertial>
      </link>
    </model>
    <joint name='right_lateral_rear_led' type='fixed'>
      <parent>/base_link</parent>
      <child>right_lateral_rear_led::body</child>
    </joint>
    <model name='left_lateral_front_led'>
      <pose frame=''>0.066047 0.212211 0.209188 -3.14159 1.56859 -1.60259</pose>
      <link name='body'>
        <pose frame=''>0 0 0.0005 0 -0 0</pose>
        <visual name='light_source'>
          <geometry>
            <mesh>
              <uri>model://x1_description/meshes/led_lamp.dae</uri>
            </mesh>
          </geometry>
          <transparency>1</transparency>
          <material>
            <ambient>1 1 1 1</ambient>
            <diffuse>1 1 1 1</diffuse>
            <specular>1 1 1 1</specular>
            <emissive>0 0 0 1</emissive>
          </material>
        </visual>
        <inertial>
          <mass>1e-06</mass>
          <inertia>
            <ixx>0.001</ixx>
            <ixy>0</ixy>
            <iyy>0.001</iyy>
            <ixz>0</ixz>
            <iyz>0</iyz>
            <izz>0.001</izz>
          </inertia>
        </inertial>
      </link>
    </model>
    <joint name='left_lateral_front_led' type='fixed'>
      <parent>/base_link</parent>
      <child>left_lateral_front_led::body</child>
    </joint>
    <model name='left_lateral_rear_led'>
      <pose frame=''>-0.066047 0.212211 0.209188 -3.14159 1.56859 -1.60259</pose>
      <link name='body'>
        <pose frame=''>0 0 0.0005 0 -0 0</pose>
        <visual name='light_source'>
          <geometry>
            <mesh>
              <uri>model://x1_description/meshes/led_lamp.dae</uri>
            </mesh>
          </geometry>
          <transparency>1</transparency>
          <material>
            <ambient>1 1 1 1</ambient>
            <diffuse>1 1 1 1</diffuse>
            <specular>1 1 1 1</specular>
            <emissive>0 0 0 1</emissive>
          </material>
        </visual>
        <inertial>
          <mass>1e-06</mass>
          <inertia>
            <ixx>0.001</ixx>
            <ixy>0</ixy>
            <iyy>0.001</iyy>
            <ixz>0</ixz>
            <iyz>0</iyz>
            <izz>0.001</izz>
          </inertia>
        </inertial>
      </link>
    </model>
    <joint name='left_lateral_rear_led' type='fixed'>
      <parent>/base_link</parent>
      <child>left_lateral_rear_led::body</child>
    </joint>
    <static>1</static>
  </model>
</sdf>
