<sdf version='1.6'>
  <model name='x2'>
    <pose>0 0 0.066040 0 0 0</pose>
    <link name='//base_link'>
      <pose frame=''>0 0 0 0 -0 0</pose>
      <inertial>
        <pose frame=''>0.011999 0.002 0.066996 0 -0 0</pose>
        <mass>16.524</mass>
        <inertia>
          <ixx>0.320605</ixx>
          <ixy>-0.000800023</ixy>
          <ixz>0.0163992</ixz>
          <iyy>0.399205</iyy>
          <iyz>-0.000900133</iyz>
          <izz>0.455501</izz>
        </inertia>
      </inertial>
      <collision name='//base_link_fixed_joint_lump__//chassis_link_collision'>
        <pose frame=''>0 0 0.092 0 -0 0</pose>
        <geometry>
          <box>
            <size>0.42 0.31 0.184</size>
          </box>
        </geometry>
      </collision>
      <visual name='//base_link_fixed_joint_lump__//chassis_link_visual'>
        <pose frame=''>0 0 -0.0655 1.5708 0 -1.5708</pose>
        <geometry>
          <mesh>
            <scale>1 1 1</scale>
            <uri>model://x2_description/meshes/x2_chassis.dae</uri>
          </mesh>
        </geometry>
      </visual>
      <visual name='//base_link_fixed_joint_lump__//navsat_link_visual_1'>
        <pose frame=''>-0.18 0.126 0.1895 0 -0 0</pose>
        <geometry>
          <cylinder>
            <length>0.016</length>
            <radius>0.026</radius>
          </cylinder>
        </geometry>
      </visual>
      <visual name='//base_link_fixed_joint_lump__//center_left_headlight_link_visual_2'>
        <pose frame=''>0.22 0.05 0.0845 0 -0 -3.14159</pose>
        <geometry>
          <mesh>
            <scale>1 1 1</scale>
            <uri>model://x2_description/meshes/headlight.dae</uri>
          </mesh>
        </geometry>
      </visual>
      <visual name='//base_link_fixed_joint_lump__//center_right_headlight_link_visual_3'>
        <pose frame=''>0.22 -0.05 0.0845 0 -0 -3.14159</pose>
        <geometry>
          <mesh>
            <scale>1 1 1</scale>
            <uri>model://x2_description/meshes/headlight.dae</uri>
          </mesh>
        </geometry>
      </visual>
      <visual name='//base_link_fixed_joint_lump__//left_headlight_link_visual_4'>
        <pose frame=''>0.22 0.145 0.0845 0 -0 -3.14159</pose>
        <geometry>
          <mesh>
            <scale>1 1 1</scale>
            <uri>model://x2_description/meshes/headlight.dae</uri>
          </mesh>
        </geometry>
      </visual>
      <visual name='//base_link_fixed_joint_lump__marker_visual_5'>
        <pose frame=''>0 0.187795 0.15 -3.14159 1.57079 -1.60259</pose>
        <geometry>
          <mesh>
            <scale>1 1 1</scale>
            <uri>model://x2_description/meshes/led.dae</uri>
          </mesh>
        </geometry>
      </visual>
      <visual name='//base_link_fixed_joint_lump__marker_visual_6'>
        <pose frame=''>-0.258 0 0.165 3.14159 1.57079 7e-06</pose>
        <geometry>
          <mesh>
            <scale>1 1 1</scale>
            <uri>model://x2_description/meshes/led.dae</uri>
          </mesh>
        </geometry>
      </visual>
      <visual name='//base_link_fixed_joint_lump__//right_headlight_link_visual_7'>
        <pose frame=''>0.22 -0.145 0.0845 0 -0 -3.14159</pose>
        <geometry>
          <mesh>
            <scale>1 1 1</scale>
            <uri>model://x2_description/meshes/headlight.dae</uri>
          </mesh>
        </geometry>
      </visual>
      <visual name='//base_link_fixed_joint_lump__marker_visual_8'>
        <pose frame=''>0 -0.187795 0.15 3.14159 1.57079 1.60259</pose>
        <geometry>
          <mesh>
            <scale>1 1 1</scale>
            <uri>model://x2_description/meshes/led.dae</uri>
          </mesh>
        </geometry>
      </visual>
    </link>
    <link name='//front_left_wheel_link'>
      <pose frame=''>0.131 0.187795 0.0345 0 -0 0</pose>
      <inertial>
        <pose frame=''>0 0 0 0 -0 0</pose>
        <mass>0.477</mass>
        <inertia>
          <ixx>0.0013</ixx>
          <ixy>0</ixy>
          <ixz>0</ixz>
          <iyy>0.0024</iyy>
          <iyz>0</iyz>
          <izz>0.0013</izz>
        </inertia>
      </inertial>
      <collision name='//front_left_wheel_link_collision'>
        <pose frame=''>0 0 0 1.5708 -0 0</pose>
        <geometry>
          <cylinder>
            <length>0.04</length>
            <radius>0.098</radius>
          </cylinder>
        </geometry>
        <surface>
          <contact>
            <ode/>
          </contact>
          <friction>
            <ode/>
          </friction>
        </surface>
      </collision>
      <visual name='//front_left_wheel_link_visual'>
        <pose frame=''>0 0 0 1.5708 -0 0</pose>
        <geometry>
          <mesh>
            <scale>1 1 1</scale>
            <uri>model://x2_description/meshes/x2_wheel_left.dae</uri>
          </mesh>
        </geometry>
        <material>
          <script>
            <name>Gazebo/DarkGrey</name>
            <uri>file://media/materials/scripts/gazebo.material</uri>
          </script>
        </material>
      </visual>
      <gravity>1</gravity>
      <velocity_decay/>
    </link>
    <joint name='front_left_wheel' type='revolute'>
      <child>//front_left_wheel_link</child>
      <parent>//base_link</parent>
      <axis>
        <xyz>0 1 0</xyz>
        <limit>
          <lower>-1e+16</lower>
          <upper>1e+16</upper>
        </limit>
        <dynamics>
          <spring_reference>0</spring_reference>
          <spring_stiffness>0</spring_stiffness>
        </dynamics>
        <use_parent_model_frame>1</use_parent_model_frame>
      </axis>
    </joint>
    <link name='//front_right_wheel_link'>
      <pose frame=''>0.131 -0.187795 0.0345 0 -0 0</pose>
      <inertial>
        <pose frame=''>0 0 0 0 -0 0</pose>
        <mass>0.477</mass>
        <inertia>
          <ixx>0.0013</ixx>
          <ixy>0</ixy>
          <ixz>0</ixz>
          <iyy>0.0024</iyy>
          <iyz>0</iyz>
          <izz>0.0013</izz>
        </inertia>
      </inertial>
      <collision name='//front_right_wheel_link_collision'>
        <pose frame=''>0 0 0 1.5708 -0 0</pose>
        <geometry>
          <cylinder>
            <length>0.04</length>
            <radius>0.098</radius>
          </cylinder>
        </geometry>
        <surface>
          <contact>
            <ode/>
          </contact>
          <friction>
            <ode/>
          </friction>
        </surface>
      </collision>
      <visual name='//front_right_wheel_link_visual'>
        <pose frame=''>0 0 0 1.5708 -0 0</pose>
        <geometry>
          <mesh>
            <scale>1 1 1</scale>
            <uri>model://x2_description/meshes/x2_wheel_right.dae</uri>
          </mesh>
        </geometry>
        <material>
          <script>
            <name>Gazebo/DarkGrey</name>
            <uri>file://media/materials/scripts/gazebo.material</uri>
          </script>
        </material>
      </visual>
      <gravity>1</gravity>
      <velocity_decay/>
    </link>
    <joint name='front_right_wheel' type='revolute'>
      <child>//front_right_wheel_link</child>
      <parent>//base_link</parent>
      <axis>
        <xyz>0 1 0</xyz>
        <limit>
          <lower>-1e+16</lower>
          <upper>1e+16</upper>
        </limit>
        <dynamics>
          <spring_reference>0</spring_reference>
          <spring_stiffness>0</spring_stiffness>
        </dynamics>
        <use_parent_model_frame>1</use_parent_model_frame>
      </axis>
    </joint>
    <link name='//rear_left_wheel_link'>
      <pose frame=''>-0.131 0.187795 0.0345 0 -0 0</pose>
      <inertial>
        <pose frame=''>0 0 0 0 -0 0</pose>
        <mass>0.477</mass>
        <inertia>
          <ixx>0.0013</ixx>
          <ixy>0</ixy>
          <ixz>0</ixz>
          <iyy>0.0024</iyy>
          <iyz>0</iyz>
          <izz>0.0013</izz>
        </inertia>
      </inertial>
      <collision name='//rear_left_wheel_link_collision'>
        <pose frame=''>0 0 0 1.5708 -0 0</pose>
        <geometry>
          <cylinder>
            <length>0.04</length>
            <radius>0.098</radius>
          </cylinder>
        </geometry>
        <surface>
          <contact>
            <ode/>
          </contact>
          <friction>
            <ode/>
          </friction>
        </surface>
      </collision>
      <visual name='//rear_left_wheel_link_visual'>
        <pose frame=''>0 0 0 1.5708 -0 0</pose>
        <geometry>
          <mesh>
            <scale>1 1 1</scale>
            <uri>model://x2_description/meshes/x2_wheel_left.dae</uri>
          </mesh>
        </geometry>
        <material>
          <script>
            <name>Gazebo/DarkGrey</name>
            <uri>file://media/materials/scripts/gazebo.material</uri>
          </script>
        </material>
      </visual>
      <gravity>1</gravity>
      <velocity_decay/>
    </link>
    <joint name='rear_left_wheel' type='revolute'>
      <child>//rear_left_wheel_link</child>
      <parent>//base_link</parent>
      <axis>
        <xyz>0 1 0</xyz>
        <limit>
          <lower>-1e+16</lower>
          <upper>1e+16</upper>
        </limit>
        <dynamics>
          <spring_reference>0</spring_reference>
          <spring_stiffness>0</spring_stiffness>
        </dynamics>
        <use_parent_model_frame>1</use_parent_model_frame>
      </axis>
    </joint>
    <link name='//rear_right_wheel_link'>
      <pose frame=''>-0.131 -0.187795 0.0345 0 -0 0</pose>
      <inertial>
        <pose frame=''>0 0 0 0 -0 0</pose>
        <mass>0.477</mass>
        <inertia>
          <ixx>0.0013</ixx>
          <ixy>0</ixy>
          <ixz>0</ixz>
          <iyy>0.0024</iyy>
          <iyz>0</iyz>
          <izz>0.0013</izz>
        </inertia>
      </inertial>
      <collision name='//rear_right_wheel_link_collision'>
        <pose frame=''>0 0 0 1.5708 -0 0</pose>
        <geometry>
          <cylinder>
            <length>0.04</length>
            <radius>0.098</radius>
          </cylinder>
        </geometry>
        <surface>
          <contact>
            <ode/>
          </contact>
          <friction>
            <ode/>
          </friction>
        </surface>
      </collision>
      <visual name='//rear_right_wheel_link_visual'>
        <pose frame=''>0 0 0 1.5708 -0 0</pose>
        <geometry>
          <mesh>
            <scale>1 1 1</scale>
            <uri>model://x2_description/meshes/x2_wheel_right.dae</uri>
          </mesh>
        </geometry>
        <material>
          <script>
            <name>Gazebo/DarkGrey</name>
            <uri>file://media/materials/scripts/gazebo.material</uri>
          </script>
        </material>
      </visual>
      <gravity>1</gravity>
      <velocity_decay/>
    </link>
    <joint name='rear_right_wheel' type='revolute'>
      <child>//rear_right_wheel_link</child>
      <parent>//base_link</parent>
      <axis>
        <xyz>0 1 0</xyz>
        <limit>
          <lower>-1e+16</lower>
          <upper>1e+16</upper>
        </limit>
        <dynamics>
          <spring_reference>0</spring_reference>
          <spring_stiffness>0</spring_stiffness>
        </dynamics>
        <use_parent_model_frame>1</use_parent_model_frame>
      </axis>
    </joint>
    <model name='left_headlight'>
      <pose frame=''>0.22 0.145 0.0845 0 -0 -3.14159</pose>
      <link name='body'>
        <pose frame=''>-0.0005 0 0 0 -0 0</pose>
        <visual name='light_source'>
          <geometry>
            <mesh>
              <uri>model://x2_description/meshes/headlight_lamp.dae</uri>
            </mesh>
          </geometry>
          <transparency>1</transparency>
          <material>
            <ambient>1 1 1 1</ambient>
            <diffuse>1 1 1 1</diffuse>
            <specular>1 1 1 1</specular>
            <emissive>0 0 0 1</emissive>
          </material>
        </visual>
        <inertial>
          <mass>1e-06</mass>
          <inertia>
            <ixx>0.001</ixx>
            <ixy>0</ixy>
            <iyy>0.001</iyy>
            <ixz>0</ixz>
            <iyz>0</iyz>
            <izz>0.001</izz>
          </inertia>
        </inertial>
      </link>
    </model>
    <joint name='left_headlight' type='fixed'>
      <parent>//base_link</parent>
      <child>left_headlight::body</child>
    </joint>
    <model name='right_headlight'>
      <pose frame=''>0.22 -0.145 0.0845 0 -0 -3.14159</pose>
      <link name='body'>
        <pose frame=''>-0.0005 0 0 0 -0 0</pose>
        <visual name='light_source'>
          <geometry>
            <mesh>
              <uri>model://x2_description/meshes/headlight_lamp.dae</uri>
            </mesh>
          </geometry>
          <transparency>1</transparency>
          <material>
            <ambient>1 1 1 1</ambient>
            <diffuse>1 1 1 1</diffuse>
            <specular>1 1 1 1</specular>
            <emissive>0 0 0 1</emissive>
          </material>
        </visual>
        <inertial>
          <mass>1e-06</mass>
          <inertia>
            <ixx>0.001</ixx>
            <ixy>0</ixy>
            <iyy>0.001</iyy>
            <ixz>0</ixz>
            <iyz>0</iyz>
            <izz>0.001</izz>
          </inertia>
        </inertial>
      </link>
    </model>
    <joint name='right_headlight' type='fixed'>
      <parent>//base_link</parent>
      <child>right_headlight::body</child>
    </joint>
    <model name='center_left_headlight'>
      <pose frame=''>0.22 0.05 0.0845 0 -0 -3.14159</pose>
      <link name='body'>
        <pose frame=''>-0.0005 0 0 0 -0 0</pose>
        <visual name='light_source'>
          <geometry>
            <mesh>
              <uri>model://x2_description/meshes/headlight_lamp.dae</uri>
            </mesh>
          </geometry>
          <transparency>1</transparency>
          <material>
            <ambient>1 1 1 1</ambient>
            <diffuse>1 1 1 1</diffuse>
            <specular>1 1 1 1</specular>
            <emissive>0 0 0 1</emissive>
          </material>
        </visual>
        <inertial>
          <mass>1e-06</mass>
          <inertia>
            <ixx>0.001</ixx>
            <ixy>0</ixy>
            <iyy>0.001</iyy>
            <ixz>0</ixz>
            <iyz>0</iyz>
            <izz>0.001</izz>
          </inertia>
        </inertial>
      </link>
    </model>
    <joint name='center_left_headlight' type='fixed'>
      <parent>//base_link</parent>
      <child>center_left_headlight::body</child>
    </joint>
    <model name='center_right_headlight'>
      <pose frame=''>0.22 -0.05 0.0845 0 -0 -3.14159</pose>
      <link name='body'>
        <pose frame=''>-0.0005 0 0 0 -0 0</pose>
        <visual name='light_source'>
          <geometry>
            <mesh>
              <uri>model://x2_description/meshes/headlight_lamp.dae</uri>
            </mesh>
          </geometry>
          <transparency>1</transparency>
          <material>
            <ambient>1 1 1 1</ambient>
            <diffuse>1 1 1 1</diffuse>
            <specular>1 1 1 1</specular>
            <emissive>0 0 0 1</emissive>
          </material>
        </visual>
        <inertial>
          <mass>1e-06</mass>
          <inertia>
            <ixx>0.001</ixx>
            <ixy>0</ixy>
            <iyy>0.001</iyy>
            <ixz>0</ixz>
            <iyz>0</iyz>
            <izz>0.001</izz>
          </inertia>
        </inertial>
      </link>
    </model>
    <joint name='center_right_headlight' type='fixed'>
      <parent>//base_link</parent>
      <child>center_right_headlight::body</child>
    </joint>
    <model name='rear_center_led'>
      <pose frame=''>-0.258 0 0.165 -3.14159 1.56859 7e-06</pose>
      <link name='body'>
        <pose frame=''>0 0 0.0005 0 -0 0</pose>
        <visual name='light_source'>
          <geometry>
            <mesh>
              <uri>model://x2_description/meshes/led_lamp.dae</uri>
            </mesh>
          </geometry>
          <transparency>1</transparency>
          <material>
            <ambient>1 1 1 1</ambient>
            <diffuse>1 1 1 1</diffuse>
            <specular>1 1 1 1</specular>
            <emissive>0 0 0 1</emissive>
          </material>
        </visual>
        <inertial>
          <mass>1e-06</mass>
          <inertia>
            <ixx>0.001</ixx>
            <ixy>0</ixy>
            <iyy>0.001</iyy>
            <ixz>0</ixz>
            <iyz>0</iyz>
            <izz>0.001</izz>
          </inertia>
        </inertial>
      </link>
    </model>
    <joint name='rear_center_led' type='fixed'>
      <parent>//base_link</parent>
      <child>rear_center_led::body</child>
    </joint>
    <model name='right_lateral_led'>
      <pose frame=''>0 -0.187795 0.15 3.14159 1.56859 1.60259</pose>
      <link name='body'>
        <pose frame=''>0 0 0.0005 0 -0 0</pose>
        <visual name='light_source'>
          <geometry>
            <mesh>
              <uri>model://x2_description/meshes/led_lamp.dae</uri>
            </mesh>
          </geometry>
          <transparency>1</transparency>
          <material>
            <ambient>1 1 1 1</ambient>
            <diffuse>1 1 1 1</diffuse>
            <specular>1 1 1 1</specular>
            <emissive>0 0 0 1</emissive>
          </material>
        </visual>
        <inertial>
          <mass>1e-06</mass>
          <inertia>
            <ixx>0.001</ixx>
            <ixy>0</ixy>
            <iyy>0.001</iyy>
            <ixz>0</ixz>
            <iyz>0</iyz>
            <izz>0.001</izz>
          </inertia>
        </inertial>
      </link>
    </model>
    <joint name='right_lateral_led' type='fixed'>
      <parent>//base_link</parent>
      <child>right_lateral_led::body</child>
    </joint>
    <model name='left_lateral_led'>
      <pose frame=''>0 0.187795 0.15 -3.14159 1.56859 -1.60259</pose>
      <link name='body'>
        <pose frame=''>0 0 0.0005 0 -0 0</pose>
        <visual name='light_source'>
          <geometry>
            <mesh>
              <uri>model://x2_description/meshes/led_lamp.dae</uri>
            </mesh>
          </geometry>
          <transparency>1</transparency>
          <material>
            <ambient>1 1 1 1</ambient>
            <diffuse>1 1 1 1</diffuse>
            <specular>1 1 1 1</specular>
            <emissive>0 0 0 1</emissive>
          </material>
        </visual>
        <inertial>
          <mass>1e-06</mass>
          <inertia>
            <ixx>0.001</ixx>
            <ixy>0</ixy>
            <iyy>0.001</iyy>
            <ixz>0</ixz>
            <iyz>0</iyz>
            <izz>0.001</izz>
          </inertia>
        </inertial>
      </link>
    </model>
    <joint name='left_lateral_led' type='fixed'>
      <parent>//base_link</parent>
      <child>left_lateral_led::body</child>
    </joint>
    <static>1</static>
  </model>
</sdf>
